<?xml version="1.0"?>
<robot name="artist_robot">

  <!-- Звено: Корпус робота -->
  <link name="base_link">
    <visual>
      <geometry>
        <!-- <mesh filename="package://artist_robot/urdf/base_link.dae"/> -->
        <box size="0.5 0.3 0.1"/>
      </geometry>
      <material name="blue">
        <color rgba="0 0 1 1"/>
      </material>
    </visual>
    <collision>
      <geometry>
        <box size="0.5 0.3 0.1"/>
      </geometry>
    </collision>
    <inertial>
      <mass value="5.0"/> <!-- Масса 5 кг -->
      <inertia ixx="0.1" ixy="0.0" ixz="0.0" iyy="0.1" iyz="0.0" izz="0.1"/>
    </inertial>
  </link>

  <link name="left_wheel">
    <visual>
      <geometry>
        <!-- <mesh filename="package://artist_robot/urdf/wheel.dae"/> -->
        <cylinder radius="0.05" length="0.02"/>
      </geometry>
      <material name="black">
        <color rgba="0 0 0 1"/>
      </material>
    </visual>
    <collision>
      <geometry>
        <cylinder radius="0.05" length="0.02"/>
      </geometry>
    </collision>
    <inertial>
      <mass value="0.5"/> <!-- Масса 0.5 кг -->
      <inertia ixx="0.001" ixy="0.0" ixz="0.0" iyy="0.001" iyz="0.0" izz="0.001"/>
    </inertial>
  </link>
  <link name="right_wheel">
    <visual>
      <geometry>
        <!-- <mesh filename="package://artist_robot/urdf/wheel.dae"/> -->
        <cylinder radius="0.05" length="0.02"/>
      </geometry>
      <material name="black">
        <color rgba="0 0 0 1"/>
      </material>
    </visual>
    <collision>
      <geometry>
        <cylinder radius="0.05" length="0.02"/>
      </geometry>
    </collision>
    <inertial>
      <mass value="0.5"/>
      <inertia ixx="0.001" ixy="0.0" ixz="0.0" iyy="0.001" iyz="0.0" izz="0.001"/>
    </inertial>
  </link>
  <link name="caster_wheel">
    <visual>
      <geometry>
        <sphere radius="0.035"/>
      </geometry>
      <material name="grey">
        <color rgba="0.6 0.6 0.6 1"/>
      </material>
    </visual>
    <collision>
      <geometry>
        <sphere radius="0.035"/>
      </geometry>
    </collision>
    <inertial>
      <mass value="0.5"/>
      <inertia ixx="0.001" ixy="0.0" ixz="0.0" iyy="0.001" iyz="0.0" izz="0.001"/>
    </inertial>
  </link>

  <link name="lift_arm">
    <visual>
      <geometry>
        <!-- <mesh filename="package://artist_robot/urdf/lift_arm.dae"/> -->
        <cylinder radius="0.05" length="0.1"/>
    </geometry>
      <material name="silver">
        <color rgba="0.8 0.8 0.8 1"/>
      </material>
    </visual>
    <collision>
        <geometry>
            <cylinder radius="0.05" length="0.1"/>
        </geometry>
    </collision>
    <inertial>
        <mass value="0.5"/>
        <inertia ixx="0.01" ixy="0.0" ixz="0.0" iyy="0.01" iyz="0.0" izz="0.01"/>
    </inertial>
  </link>

  <!-- Звено: Платформа кисти -->
  <link name="brush_platform">
    <visual>
      <geometry>
        <!-- <mesh filename="package://artist_robot/urdf/brush_platform.dae"/> -->
        <box size="0.2 0.2 0.02"/>
      </geometry>
      <material name="red">
        <color rgba="1 0 0 1"/>
      </material>
    </visual>
    <collision>
      <geometry>
        <box size="0.2 0.2 0.02"/>
      </geometry>
    </collision>
    <inertial>
      <mass value="0.2"/>
      <inertia ixx="0.001" ixy="0.0" ixz="0.0" iyy="0.001" iyz="0.0" izz="0.001"/>
    </inertial>
  </link>

  <!-- Звено: Рычаг кисти -->
  <link name="brush_arm">
    <visual>
      <geometry>
        <box size="0.05 0.05 0.1"/>
        <!-- <mesh filename="package://artist_robot/urdf/brush_arm.dae"/> -->
      </geometry>
      <material name="green">
        <color rgba="0 1 0 1"/>
      </material>
    </visual>
    <collision>
      <geometry>
        <box size="0.05 0.05 0.1"/>
      </geometry>
    </collision>
    <inertial>
      <mass value="0.1"/>
      <inertia ixx="0.001" ixy="0.0" ixz="0.0" iyy="0.001" iyz="0.0" izz="0.001"/>
    </inertial>
  </link>

  <!-- Звено: Кончик кисти -->
  <link name="brush_tip">
    <visual>
      <geometry>
        <!-- <mesh filename="package://artist_robot/urdf/brush_tip.dae"/> -->
        <cylinder radius="0.01" length="0.05"/>
      </geometry>
      <material name="yellow">
        <color rgba="1 1 0 1"/>
      </material>
    </visual>
    <collision>
      <geometry>
        <cylinder radius="0.01" length="0.05"/>
      </geometry>
    </collision>
    <inertial>
      <mass value="0.05"/>
      <inertia ixx="0.0001" ixy="0.0" ixz="0.0" iyy="0.0001" iyz="0.0" izz="0.0001"/>
    </inertial>
  </link>

  <!-- Звено: Выдвижная часть кисти -->
  <link name="brush_tip_extension">
    <visual>
      <geometry>
        <cylinder radius="0.008" length="0.05"/>
        <!-- <mesh filename="package://artist_robot/urdf/brush_tip_extension.dae"/> -->
      </geometry>
      <material name="yellow"/>
    </visual>
    <collision>
      <geometry>
        <cylinder radius="0.008" length="0.05"/>
      </geometry>
    </collision>
    <inertial>
      <mass value="0.03"/>
      <inertia ixx="0.0001" ixy="0.0" ixz="0.0" iyy="0.0001" iyz="0.0" izz="0.0001"/>
    </inertial>
  </link>

  <!-- Соединения -->

  <!-- Колеса к креплениям/корпусу (continuous для движения) -->
  <joint name="base_to_left_wheel" type="continuous">
    <parent link="base_link"/>
    <child link="left_wheel"/>
    <origin xyz="0.2 0.15 -0.05" rpy="1.5708 0 0"/> <!-- Поворот на 90° вокруг X -->
    <axis xyz="0 0 1"/> <!-- Вращение вокруг локальной Y (глобальная Y) -->
  </joint>
  <joint name="base_to_right_wheel" type="continuous">
    <parent link="base_link"/>
    <child link="right_wheel"/>
    <origin xyz="0.2 -0.15 -0.05" rpy="1.5708 0 0"/> <!-- Поворот на 90° вокруг X -->
    <axis xyz="0 0 1"/> <!-- Вращение вокруг локальной Y -->
  </joint>
  <joint name="base_to_caster_wheel" type="fixed">
    <parent link="base_link"/>
    <child link="caster_wheel"/>
    <origin xyz="-0.2 0.0 -0.06" rpy="0 0 0"/> <!-- Заднее левое -->
  </joint>
  
  <joint name="base_to_lift_arm" type="prismatic">
    <parent link="base_link"/>
    <child link="lift_arm"/>
    <origin xyz="0 0 0.05" rpy="0 0 0"/>
    <axis xyz="0 0 1"/> <!-- Движение по Z -->
    <limit lower="0" upper="0.5" effort="20" velocity="0.2"/> <!-- 0–50 см -->
  </joint>
  <joint name="lift_arm_to_brush_platform" type="fixed">
      <parent link="lift_arm"/>
      <child link="brush_platform"/>
      <origin xyz="0 0 0.05"/>
  </joint>

  <!-- Рычаг кисти к платформе (planar joint) -->
  <joint name="platform_to_brush_arm" type="prismatic">
    <parent link="brush_platform"/>
    <child link="brush_arm"/>
    <origin xyz="0 0 0.01"/> <!-- Слегка выше платформы -->
    <axis xyz="1 0 0"/>
    <limit effort="10" velocity="0.1" lower="-0.1" upper="0.1"/> <!-- Ограничение ±10 см -->
  </joint>

  <!-- Кончик кисти к рычагу (revolute joint) -->
  <joint name="arm_to_brush_tip" type="revolute">
    <parent link="brush_arm"/>
    <child link="brush_tip"/>
    <origin xyz="0 0 0.05" rpy="0 0 0"/> <!-- На конце рычага -->
    <axis xyz="1 0 0"/> <!-- Вращение вокруг оси X -->
    <limit lower="-1.57" upper="1.57" effort="10" velocity="1"/> <!-- ±90° -->
  </joint>

  <!-- Выдвижение кончика кисти (prismatic joint) -->
  <joint name="brush_tip_to_extension" type="prismatic">
    <parent link="brush_tip"/>
    <child link="brush_tip_extension"/>
    <origin xyz="0 0 0.025"/> <!-- Смещение на половину длины brush_tip -->
    <axis xyz="0 0 1"/> <!-- Выдвижение по оси Z -->
    <limit lower="0" upper="0.25" effort="10" velocity="0.1"/> <!-- Выдвижение до 5 см -->
  </joint>
</robot>
